[2024-05-01T10:50:21.349+0000] {taskinstance.py:1979} INFO - Dependencies all met for dep_context=non-requeueable deps ti=<TaskInstance: load_data_to_bq.load_data_to_bq manual__2024-05-01T10:50:00.463145+00:00 [queued]>
[2024-05-01T10:50:21.375+0000] {taskinstance.py:1979} INFO - Dependencies all met for dep_context=requeueable deps ti=<TaskInstance: load_data_to_bq.load_data_to_bq manual__2024-05-01T10:50:00.463145+00:00 [queued]>
[2024-05-01T10:50:21.376+0000] {taskinstance.py:2193} INFO - Starting attempt 1 of 1
[2024-05-01T10:50:21.414+0000] {taskinstance.py:2217} INFO - Executing <Task(PythonOperator): load_data_to_bq> on 2024-05-01 10:50:00.463145+00:00
[2024-05-01T10:50:21.432+0000] {standard_task_runner.py:60} INFO - Started process 59611 to run task
[2024-05-01T10:50:21.442+0000] {standard_task_runner.py:87} INFO - Running: ['***', 'tasks', 'run', 'load_data_to_bq', 'load_data_to_bq', 'manual__2024-05-01T10:50:00.463145+00:00', '--job-id', '1628', '--raw', '--subdir', 'DAGS_FOLDER/get_and_load.py', '--cfg-path', '/tmp/tmper5hyzcp']
[2024-05-01T10:50:21.449+0000] {standard_task_runner.py:88} INFO - Job 1628: Subtask load_data_to_bq
[2024-05-01T10:50:21.602+0000] {task_command.py:423} INFO - Running <TaskInstance: load_data_to_bq.load_data_to_bq manual__2024-05-01T10:50:00.463145+00:00 [running]> on host 283945e4dc51
[2024-05-01T10:50:21.957+0000] {taskinstance.py:2513} INFO - Exporting env vars: AIRFLOW_CTX_DAG_OWNER='***' AIRFLOW_CTX_DAG_ID='load_data_to_bq' AIRFLOW_CTX_TASK_ID='load_data_to_bq' AIRFLOW_CTX_EXECUTION_DATE='2024-05-01T10:50:00.463145+00:00' AIRFLOW_CTX_TRY_NUMBER='1' AIRFLOW_CTX_DAG_RUN_ID='manual__2024-05-01T10:50:00.463145+00:00'
[2024-05-01T10:50:21.962+0000] {get_and_load.py:137} INFO - *** gcs bucket : ds525-capstone-test-49
[2024-05-01T10:50:21.963+0000] {get_and_load.py:138} INFO - *** gcs_csv_object : staging/data_to_load.csv
[2024-05-01T10:50:22.016+0000] {taskinstance.py:2731} ERROR - Task failed with exception
Traceback (most recent call last):
  File "/home/airflow/.local/lib/python3.8/site-packages/airflow/models/taskinstance.py", line 444, in _execute_task
    result = _execute_callable(context=context, **execute_callable_kwargs)
  File "/home/airflow/.local/lib/python3.8/site-packages/airflow/models/taskinstance.py", line 414, in _execute_callable
    return execute_callable(context=context, **execute_callable_kwargs)
  File "/home/airflow/.local/lib/python3.8/site-packages/airflow/operators/python.py", line 200, in execute
    return_value = self.execute_callable()
  File "/home/airflow/.local/lib/python3.8/site-packages/airflow/operators/python.py", line 217, in execute_callable
    return self.python_callable(*self.op_args, **self.op_kwargs)
  File "/opt/airflow/dags/get_and_load.py", line 169, in _load_data_to_bq
    gcsto_bq_op.execute(context=None)
  File "/home/airflow/.local/lib/python3.8/site-packages/airflow/providers/google/cloud/transfers/gcs_to_bigquery.py", line 322, in execute
    hook = BigQueryHook(
  File "/home/airflow/.local/lib/python3.8/site-packages/airflow/providers/google/cloud/hooks/bigquery.py", line 119, in __init__
    super().__init__(
  File "/home/airflow/.local/lib/python3.8/site-packages/airflow/providers/google/common/hooks/base_google.py", line 251, in __init__
    self.extras: dict = self.get_connection(self.gcp_conn_id).extra_dejson
  File "/home/airflow/.local/lib/python3.8/site-packages/airflow/hooks/base.py", line 82, in get_connection
    conn = Connection.get_connection_from_secrets(conn_id)
  File "/home/airflow/.local/lib/python3.8/site-packages/airflow/models/connection.py", line 514, in get_connection_from_secrets
    raise AirflowNotFoundException(f"The conn_id `{conn_id}` isn't defined")
airflow.exceptions.AirflowNotFoundException: The conn_id `google_cloud_default` isn't defined
[2024-05-01T10:50:22.030+0000] {taskinstance.py:1149} INFO - Marking task as FAILED. dag_id=load_data_to_bq, task_id=load_data_to_bq, execution_date=20240501T105000, start_date=20240501T105021, end_date=20240501T105022
[2024-05-01T10:50:22.063+0000] {standard_task_runner.py:107} ERROR - Failed to execute job 1628 for task load_data_to_bq (The conn_id `google_cloud_default` isn't defined; 59611)
[2024-05-01T10:50:22.097+0000] {local_task_job_runner.py:234} INFO - Task exited with return code 1
[2024-05-01T10:50:22.145+0000] {taskinstance.py:3312} INFO - 0 downstream tasks scheduled from follow-on schedule check
