[2024-03-25T18:43:03.077+0000] {taskinstance.py:1979} INFO - Dependencies all met for dep_context=non-requeueable deps ti=<TaskInstance: test_get_up_gcs.upload_to_gcs manual__2024-03-25T18:35:23.455213+00:00 [queued]>
[2024-03-25T18:43:03.106+0000] {taskinstance.py:1979} INFO - Dependencies all met for dep_context=requeueable deps ti=<TaskInstance: test_get_up_gcs.upload_to_gcs manual__2024-03-25T18:35:23.455213+00:00 [queued]>
[2024-03-25T18:43:03.108+0000] {taskinstance.py:2193} INFO - Starting attempt 3 of 3
[2024-03-25T18:43:03.150+0000] {taskinstance.py:2217} INFO - Executing <Task(LocalFilesystemToGCSOperator): upload_to_gcs> on 2024-03-25 18:35:23.455213+00:00
[2024-03-25T18:43:03.164+0000] {standard_task_runner.py:60} INFO - Started process 3598 to run task
[2024-03-25T18:43:03.175+0000] {standard_task_runner.py:87} INFO - Running: ['***', 'tasks', 'run', 'test_get_up_gcs', 'upload_to_gcs', 'manual__2024-03-25T18:35:23.455213+00:00', '--job-id', '33', '--raw', '--subdir', 'DAGS_FOLDER/test_get_up_gcs.py', '--cfg-path', '/tmp/tmpkc8if6na']
[2024-03-25T18:43:03.182+0000] {standard_task_runner.py:88} INFO - Job 33: Subtask upload_to_gcs
[2024-03-25T18:43:03.307+0000] {task_command.py:423} INFO - Running <TaskInstance: test_get_up_gcs.upload_to_gcs manual__2024-03-25T18:35:23.455213+00:00 [running]> on host c5a6ac367c49
[2024-03-25T18:43:03.546+0000] {taskinstance.py:2513} INFO - Exporting env vars: AIRFLOW_CTX_DAG_OWNER='***' AIRFLOW_CTX_DAG_ID='test_get_up_gcs' AIRFLOW_CTX_TASK_ID='upload_to_gcs' AIRFLOW_CTX_EXECUTION_DATE='2024-03-25T18:35:23.455213+00:00' AIRFLOW_CTX_TRY_NUMBER='3' AIRFLOW_CTX_DAG_RUN_ID='manual__2024-03-25T18:35:23.455213+00:00'
[2024-03-25T18:43:03.572+0000] {connection.py:269} WARNING - Connection schemes (type: google_cloud_platform) shall not contain '_' according to RFC3986.
[2024-03-25T18:43:03.584+0000] {base.py:83} INFO - Using connection ID 'my_gcp_conn' for task execution.
[2024-03-25T18:43:03.911+0000] {taskinstance.py:2731} ERROR - Task failed with exception
Traceback (most recent call last):
  File "/home/airflow/.local/lib/python3.8/site-packages/airflow/models/taskinstance.py", line 444, in _execute_task
    result = _execute_callable(context=context, **execute_callable_kwargs)
  File "/home/airflow/.local/lib/python3.8/site-packages/airflow/models/taskinstance.py", line 414, in _execute_callable
    return execute_callable(context=context, **execute_callable_kwargs)
  File "/home/airflow/.local/lib/python3.8/site-packages/airflow/providers/google/cloud/transfers/local_to_gcs.py", line 110, in execute
    hook.upload(
  File "/home/airflow/.local/lib/python3.8/site-packages/airflow/providers/google/cloud/hooks/gcs.py", line 551, in upload
    _call_with_retry(
  File "/home/airflow/.local/lib/python3.8/site-packages/airflow/providers/google/cloud/hooks/gcs.py", line 509, in _call_with_retry
    f()
  File "/home/airflow/.local/lib/python3.8/site-packages/google/cloud/storage/blob.py", line 2949, in upload_from_filename
    self._handle_filename_and_upload(
  File "/home/airflow/.local/lib/python3.8/site-packages/google/cloud/storage/blob.py", line 2817, in _handle_filename_and_upload
    with open(filename, "rb") as file_obj:
IsADirectoryError: [Errno 21] Is a directory: '/opt/airflow/dags/'
[2024-03-25T18:43:03.936+0000] {taskinstance.py:1149} INFO - Marking task as FAILED. dag_id=test_get_up_gcs, task_id=upload_to_gcs, execution_date=20240325T183523, start_date=20240325T184303, end_date=20240325T184303
[2024-03-25T18:43:03.970+0000] {standard_task_runner.py:107} ERROR - Failed to execute job 33 for task upload_to_gcs ([Errno 21] Is a directory: '/opt/airflow/dags/'; 3598)
[2024-03-25T18:43:04.030+0000] {local_task_job_runner.py:234} INFO - Task exited with return code 1
[2024-03-25T18:43:04.076+0000] {taskinstance.py:3312} INFO - 0 downstream tasks scheduled from follow-on schedule check
