[2024-03-25T18:36:51.412+0000] {taskinstance.py:1979} INFO - Dependencies all met for dep_context=non-requeueable deps ti=<TaskInstance: test_get_up_gcs.upload_to_gcs manual__2024-03-25T18:35:23.455213+00:00 [queued]>
[2024-03-25T18:36:51.452+0000] {taskinstance.py:1979} INFO - Dependencies all met for dep_context=requeueable deps ti=<TaskInstance: test_get_up_gcs.upload_to_gcs manual__2024-03-25T18:35:23.455213+00:00 [queued]>
[2024-03-25T18:36:51.454+0000] {taskinstance.py:2193} INFO - Starting attempt 1 of 1
[2024-03-25T18:36:51.508+0000] {taskinstance.py:2217} INFO - Executing <Task(LocalFilesystemToGCSOperator): upload_to_gcs> on 2024-03-25 18:35:23.455213+00:00
[2024-03-25T18:36:51.522+0000] {standard_task_runner.py:60} INFO - Started process 3388 to run task
[2024-03-25T18:36:51.536+0000] {standard_task_runner.py:87} INFO - Running: ['***', 'tasks', 'run', 'test_get_up_gcs', 'upload_to_gcs', 'manual__2024-03-25T18:35:23.455213+00:00', '--job-id', '24', '--raw', '--subdir', 'DAGS_FOLDER/test_get_up_gcs.py', '--cfg-path', '/tmp/tmpgke9yp2t']
[2024-03-25T18:36:51.543+0000] {standard_task_runner.py:88} INFO - Job 24: Subtask upload_to_gcs
[2024-03-25T18:36:51.672+0000] {task_command.py:423} INFO - Running <TaskInstance: test_get_up_gcs.upload_to_gcs manual__2024-03-25T18:35:23.455213+00:00 [running]> on host c5a6ac367c49
[2024-03-25T18:36:51.912+0000] {taskinstance.py:2513} INFO - Exporting env vars: AIRFLOW_CTX_DAG_OWNER='***' AIRFLOW_CTX_DAG_ID='test_get_up_gcs' AIRFLOW_CTX_TASK_ID='upload_to_gcs' AIRFLOW_CTX_EXECUTION_DATE='2024-03-25T18:35:23.455213+00:00' AIRFLOW_CTX_TRY_NUMBER='1' AIRFLOW_CTX_DAG_RUN_ID='manual__2024-03-25T18:35:23.455213+00:00'
[2024-03-25T18:36:51.937+0000] {connection.py:269} WARNING - Connection schemes (type: google_cloud_platform) shall not contain '_' according to RFC3986.
[2024-03-25T18:36:51.949+0000] {base.py:83} INFO - Using connection ID 'my_gcp_conn' for task execution.
[2024-03-25T18:36:52.287+0000] {taskinstance.py:2731} ERROR - Task failed with exception
Traceback (most recent call last):
  File "/home/airflow/.local/lib/python3.8/site-packages/airflow/models/taskinstance.py", line 444, in _execute_task
    result = _execute_callable(context=context, **execute_callable_kwargs)
  File "/home/airflow/.local/lib/python3.8/site-packages/airflow/models/taskinstance.py", line 414, in _execute_callable
    return execute_callable(context=context, **execute_callable_kwargs)
  File "/home/airflow/.local/lib/python3.8/site-packages/airflow/providers/google/cloud/transfers/local_to_gcs.py", line 110, in execute
    hook.upload(
  File "/home/airflow/.local/lib/python3.8/site-packages/airflow/providers/google/cloud/hooks/gcs.py", line 551, in upload
    _call_with_retry(
  File "/home/airflow/.local/lib/python3.8/site-packages/airflow/providers/google/cloud/hooks/gcs.py", line 509, in _call_with_retry
    f()
  File "/home/airflow/.local/lib/python3.8/site-packages/google/cloud/storage/blob.py", line 2949, in upload_from_filename
    self._handle_filename_and_upload(
  File "/home/airflow/.local/lib/python3.8/site-packages/google/cloud/storage/blob.py", line 2817, in _handle_filename_and_upload
    with open(filename, "rb") as file_obj:
IsADirectoryError: [Errno 21] Is a directory: '/opt/airflow/dags/'
[2024-03-25T18:36:52.312+0000] {taskinstance.py:1149} INFO - Marking task as FAILED. dag_id=test_get_up_gcs, task_id=upload_to_gcs, execution_date=20240325T183523, start_date=20240325T183651, end_date=20240325T183652
[2024-03-25T18:36:52.344+0000] {standard_task_runner.py:107} ERROR - Failed to execute job 24 for task upload_to_gcs ([Errno 21] Is a directory: '/opt/airflow/dags/'; 3388)
[2024-03-25T18:36:52.389+0000] {local_task_job_runner.py:234} INFO - Task exited with return code 1
[2024-03-25T18:36:52.437+0000] {taskinstance.py:3312} INFO - 0 downstream tasks scheduled from follow-on schedule check
