[2024-03-25T18:35:25.362+0000] {taskinstance.py:1979} INFO - Dependencies all met for dep_context=non-requeueable deps ti=<TaskInstance: test_get_up_gcs.get_data_api manual__2024-03-25T18:35:23.455213+00:00 [queued]>
[2024-03-25T18:35:25.390+0000] {taskinstance.py:1979} INFO - Dependencies all met for dep_context=requeueable deps ti=<TaskInstance: test_get_up_gcs.get_data_api manual__2024-03-25T18:35:23.455213+00:00 [queued]>
[2024-03-25T18:35:25.390+0000] {taskinstance.py:2193} INFO - Starting attempt 1 of 1
[2024-03-25T18:35:25.431+0000] {taskinstance.py:2217} INFO - Executing <Task(PythonOperator): get_data_api> on 2024-03-25 18:35:23.455213+00:00
[2024-03-25T18:35:25.443+0000] {standard_task_runner.py:60} INFO - Started process 3329 to run task
[2024-03-25T18:35:25.454+0000] {standard_task_runner.py:87} INFO - Running: ['***', 'tasks', 'run', 'test_get_up_gcs', 'get_data_api', 'manual__2024-03-25T18:35:23.455213+00:00', '--job-id', '21', '--raw', '--subdir', 'DAGS_FOLDER/test_get_up_gcs.py', '--cfg-path', '/tmp/tmpwshzc5gt']
[2024-03-25T18:35:25.463+0000] {standard_task_runner.py:88} INFO - Job 21: Subtask get_data_api
[2024-03-25T18:35:25.609+0000] {task_command.py:423} INFO - Running <TaskInstance: test_get_up_gcs.get_data_api manual__2024-03-25T18:35:23.455213+00:00 [running]> on host c5a6ac367c49
[2024-03-25T18:35:25.958+0000] {taskinstance.py:2513} INFO - Exporting env vars: AIRFLOW_CTX_DAG_OWNER='***' AIRFLOW_CTX_DAG_ID='test_get_up_gcs' AIRFLOW_CTX_TASK_ID='get_data_api' AIRFLOW_CTX_EXECUTION_DATE='2024-03-25T18:35:23.455213+00:00' AIRFLOW_CTX_TRY_NUMBER='1' AIRFLOW_CTX_DAG_RUN_ID='manual__2024-03-25T18:35:23.455213+00:00'
[2024-03-25T18:35:39.022+0000] {test_get_up_gcs.py:60} INFO - JSON data saved to /opt/***/dags/data_2024_03_26_0100.json
[2024-03-25T18:35:39.023+0000] {taskinstance.py:2731} ERROR - Task failed with exception
Traceback (most recent call last):
  File "/home/airflow/.local/lib/python3.8/site-packages/airflow/models/taskinstance.py", line 444, in _execute_task
    result = _execute_callable(context=context, **execute_callable_kwargs)
  File "/home/airflow/.local/lib/python3.8/site-packages/airflow/models/taskinstance.py", line 414, in _execute_callable
    return execute_callable(context=context, **execute_callable_kwargs)
  File "/home/airflow/.local/lib/python3.8/site-packages/airflow/operators/python.py", line 200, in execute
    return_value = self.execute_callable()
  File "/home/airflow/.local/lib/python3.8/site-packages/airflow/operators/python.py", line 217, in execute_callable
    return self.python_callable(*self.op_args, **self.op_kwargs)
  File "/opt/airflow/dags/test_get_up_gcs.py", line 64, in _get_data_api
    logging.ingo('local file path : ' + local_file_path)
AttributeError: module 'logging' has no attribute 'ingo'
[2024-03-25T18:35:39.045+0000] {taskinstance.py:1149} INFO - Marking task as FAILED. dag_id=test_get_up_gcs, task_id=get_data_api, execution_date=20240325T183523, start_date=20240325T183525, end_date=20240325T183539
[2024-03-25T18:35:39.080+0000] {standard_task_runner.py:107} ERROR - Failed to execute job 21 for task get_data_api (module 'logging' has no attribute 'ingo'; 3329)
[2024-03-25T18:35:39.109+0000] {local_task_job_runner.py:234} INFO - Task exited with return code 1
[2024-03-25T18:35:39.170+0000] {taskinstance.py:3312} INFO - 0 downstream tasks scheduled from follow-on schedule check
