[2024-05-01T10:01:07.118+0000] {taskinstance.py:1979} INFO - Dependencies all met for dep_context=non-requeueable deps ti=<TaskInstance: load_data_to_bq.load_data_to_bq manual__2024-05-01T10:00:45.303061+00:00 [queued]>
[2024-05-01T10:01:07.144+0000] {taskinstance.py:1979} INFO - Dependencies all met for dep_context=requeueable deps ti=<TaskInstance: load_data_to_bq.load_data_to_bq manual__2024-05-01T10:00:45.303061+00:00 [queued]>
[2024-05-01T10:01:07.145+0000] {taskinstance.py:2193} INFO - Starting attempt 1 of 1
[2024-05-01T10:01:07.216+0000] {taskinstance.py:2217} INFO - Executing <Task(PythonOperator): load_data_to_bq> on 2024-05-01 10:00:45.303061+00:00
[2024-05-01T10:01:07.232+0000] {standard_task_runner.py:60} INFO - Started process 56447 to run task
[2024-05-01T10:01:07.242+0000] {standard_task_runner.py:87} INFO - Running: ['***', 'tasks', 'run', 'load_data_to_bq', 'load_data_to_bq', 'manual__2024-05-01T10:00:45.303061+00:00', '--job-id', '1581', '--raw', '--subdir', 'DAGS_FOLDER/get_and_load.py', '--cfg-path', '/tmp/tmp41i1xchw']
[2024-05-01T10:01:07.249+0000] {standard_task_runner.py:88} INFO - Job 1581: Subtask load_data_to_bq
[2024-05-01T10:01:07.385+0000] {task_command.py:423} INFO - Running <TaskInstance: load_data_to_bq.load_data_to_bq manual__2024-05-01T10:00:45.303061+00:00 [running]> on host 283945e4dc51
[2024-05-01T10:01:07.670+0000] {taskinstance.py:2513} INFO - Exporting env vars: AIRFLOW_CTX_DAG_OWNER='***' AIRFLOW_CTX_DAG_ID='load_data_to_bq' AIRFLOW_CTX_TASK_ID='load_data_to_bq' AIRFLOW_CTX_EXECUTION_DATE='2024-05-01T10:00:45.303061+00:00' AIRFLOW_CTX_TRY_NUMBER='1' AIRFLOW_CTX_DAG_RUN_ID='manual__2024-05-01T10:00:45.303061+00:00'
[2024-05-01T10:01:07.674+0000] {get_and_load.py:137} INFO - *** gcs bucket : ds525-capstone-test-49
[2024-05-01T10:01:07.675+0000] {get_and_load.py:138} INFO - *** gcs_csv_object : staging/data_to_load.csv
[2024-05-01T10:01:07.701+0000] {taskinstance.py:2731} ERROR - Task failed with exception
Traceback (most recent call last):
  File "/home/airflow/.local/lib/python3.8/site-packages/airflow/models/taskinstance.py", line 444, in _execute_task
    result = _execute_callable(context=context, **execute_callable_kwargs)
  File "/home/airflow/.local/lib/python3.8/site-packages/airflow/models/taskinstance.py", line 414, in _execute_callable
    return execute_callable(context=context, **execute_callable_kwargs)
  File "/home/airflow/.local/lib/python3.8/site-packages/airflow/operators/python.py", line 200, in execute
    return_value = self.execute_callable()
  File "/home/airflow/.local/lib/python3.8/site-packages/airflow/operators/python.py", line 217, in execute_callable
    return self.python_callable(*self.op_args, **self.op_kwargs)
  File "/opt/airflow/dags/get_and_load.py", line 140, in _load_data_to_bq
    load_task = GCSToBigQueryOperator(
  File "/home/airflow/.local/lib/python3.8/site-packages/airflow/models/baseoperator.py", line 437, in apply_defaults
    result = func(self, **kwargs, default_args=default_args)
  File "/home/airflow/.local/lib/python3.8/site-packages/airflow/providers/google/cloud/transfers/gcs_to_bigquery.py", line 234, in __init__
    super().__init__(**kwargs)
  File "/home/airflow/.local/lib/python3.8/site-packages/airflow/models/baseoperator.py", line 437, in apply_defaults
    result = func(self, **kwargs, default_args=default_args)
  File "/home/airflow/.local/lib/python3.8/site-packages/airflow/models/baseoperator.py", line 811, in __init__
    task_group.add(self)
  File "/home/airflow/.local/lib/python3.8/site-packages/airflow/utils/task_group.py", line 231, in add
    raise DuplicateTaskIdFound(f"{node_type} id '{key}' has already been added to the DAG")
airflow.exceptions.DuplicateTaskIdFound: Task id 'load_data_to_bq' has already been added to the DAG
[2024-05-01T10:01:07.716+0000] {taskinstance.py:1149} INFO - Marking task as FAILED. dag_id=load_data_to_bq, task_id=load_data_to_bq, execution_date=20240501T100045, start_date=20240501T100107, end_date=20240501T100107
[2024-05-01T10:01:07.754+0000] {standard_task_runner.py:107} ERROR - Failed to execute job 1581 for task load_data_to_bq (Task id 'load_data_to_bq' has already been added to the DAG; 56447)
[2024-05-01T10:01:07.814+0000] {local_task_job_runner.py:234} INFO - Task exited with return code 1
[2024-05-01T10:01:07.860+0000] {taskinstance.py:3312} INFO - 0 downstream tasks scheduled from follow-on schedule check
