[2024-03-25T19:01:51.009+0000] {taskinstance.py:1979} INFO - Dependencies all met for dep_context=non-requeueable deps ti=<TaskInstance: test_get_up_gcs.upload_to_gcs manual__2024-03-25T18:57:23.881111+00:00 [queued]>
[2024-03-25T19:01:51.048+0000] {taskinstance.py:1979} INFO - Dependencies all met for dep_context=requeueable deps ti=<TaskInstance: test_get_up_gcs.upload_to_gcs manual__2024-03-25T18:57:23.881111+00:00 [queued]>
[2024-03-25T19:01:51.050+0000] {taskinstance.py:2193} INFO - Starting attempt 2 of 2
[2024-03-25T19:01:51.093+0000] {taskinstance.py:2217} INFO - Executing <Task(LocalFilesystemToGCSOperator): upload_to_gcs> on 2024-03-25 18:57:23.881111+00:00
[2024-03-25T19:01:51.106+0000] {standard_task_runner.py:60} INFO - Started process 4225 to run task
[2024-03-25T19:01:51.121+0000] {standard_task_runner.py:87} INFO - Running: ['***', 'tasks', 'run', 'test_get_up_gcs', 'upload_to_gcs', 'manual__2024-03-25T18:57:23.881111+00:00', '--job-id', '43', '--raw', '--subdir', 'DAGS_FOLDER/test_get_up_gcs.py', '--cfg-path', '/tmp/tmp1165cqlp']
[2024-03-25T19:01:51.127+0000] {standard_task_runner.py:88} INFO - Job 43: Subtask upload_to_gcs
[2024-03-25T19:01:51.252+0000] {task_command.py:423} INFO - Running <TaskInstance: test_get_up_gcs.upload_to_gcs manual__2024-03-25T18:57:23.881111+00:00 [running]> on host c5a6ac367c49
[2024-03-25T19:01:51.515+0000] {taskinstance.py:2513} INFO - Exporting env vars: AIRFLOW_CTX_DAG_OWNER='***' AIRFLOW_CTX_DAG_ID='test_get_up_gcs' AIRFLOW_CTX_TASK_ID='upload_to_gcs' AIRFLOW_CTX_EXECUTION_DATE='2024-03-25T18:57:23.881111+00:00' AIRFLOW_CTX_TRY_NUMBER='2' AIRFLOW_CTX_DAG_RUN_ID='manual__2024-03-25T18:57:23.881111+00:00'
[2024-03-25T19:01:51.543+0000] {connection.py:269} WARNING - Connection schemes (type: google_cloud_platform) shall not contain '_' according to RFC3986.
[2024-03-25T19:01:51.563+0000] {base.py:83} INFO - Using connection ID 'my_gcp_conn' for task execution.
[2024-03-25T19:01:52.807+0000] {gcs.py:512} ERROR - Upload attempt of object: gs://ds525-capstone-test-49/data_get.json from gs://ds525-capstone-test-49/data_get.json has failed. Attempt: 1, max 1.
[2024-03-25T19:01:52.809+0000] {taskinstance.py:2731} ERROR - Task failed with exception
Traceback (most recent call last):
  File "/home/airflow/.local/lib/python3.8/site-packages/google/cloud/storage/blob.py", line 2627, in _prep_and_do_upload
    created_json = self._do_upload(
  File "/home/airflow/.local/lib/python3.8/site-packages/google/cloud/storage/blob.py", line 2433, in _do_upload
    response = self._do_multipart_upload(
  File "/home/airflow/.local/lib/python3.8/site-packages/google/cloud/storage/blob.py", line 1946, in _do_multipart_upload
    response = upload.transmit(
  File "/home/airflow/.local/lib/python3.8/site-packages/google/resumable_media/requests/upload.py", line 153, in transmit
    return _request_helpers.wait_and_retry(
  File "/home/airflow/.local/lib/python3.8/site-packages/google/resumable_media/requests/_request_helpers.py", line 155, in wait_and_retry
    response = func()
  File "/home/airflow/.local/lib/python3.8/site-packages/google/resumable_media/requests/upload.py", line 149, in retriable_request
    self._process_response(result)
  File "/home/airflow/.local/lib/python3.8/site-packages/google/resumable_media/_upload.py", line 125, in _process_response
    _helpers.require_status_code(response, (http.client.OK,), self._get_status_code)
  File "/home/airflow/.local/lib/python3.8/site-packages/google/resumable_media/_helpers.py", line 108, in require_status_code
    raise common.InvalidResponse(
google.resumable_media.common.InvalidResponse: ('Request failed with status code', 403, 'Expected one of', 200)

During handling of the above exception, another exception occurred:

Traceback (most recent call last):
  File "/home/airflow/.local/lib/python3.8/site-packages/airflow/models/taskinstance.py", line 444, in _execute_task
    result = _execute_callable(context=context, **execute_callable_kwargs)
  File "/home/airflow/.local/lib/python3.8/site-packages/airflow/models/taskinstance.py", line 414, in _execute_callable
    return execute_callable(context=context, **execute_callable_kwargs)
  File "/home/airflow/.local/lib/python3.8/site-packages/airflow/providers/google/cloud/transfers/local_to_gcs.py", line 110, in execute
    hook.upload(
  File "/home/airflow/.local/lib/python3.8/site-packages/airflow/providers/google/cloud/hooks/gcs.py", line 551, in upload
    _call_with_retry(
  File "/home/airflow/.local/lib/python3.8/site-packages/airflow/providers/google/cloud/hooks/gcs.py", line 519, in _call_with_retry
    raise e
  File "/home/airflow/.local/lib/python3.8/site-packages/airflow/providers/google/cloud/hooks/gcs.py", line 509, in _call_with_retry
    f()
  File "/home/airflow/.local/lib/python3.8/site-packages/google/cloud/storage/blob.py", line 2949, in upload_from_filename
    self._handle_filename_and_upload(
  File "/home/airflow/.local/lib/python3.8/site-packages/google/cloud/storage/blob.py", line 2819, in _handle_filename_and_upload
    self._prep_and_do_upload(
  File "/home/airflow/.local/lib/python3.8/site-packages/google/cloud/storage/blob.py", line 2645, in _prep_and_do_upload
    _raise_from_invalid_response(exc)
  File "/home/airflow/.local/lib/python3.8/site-packages/google/cloud/storage/blob.py", line 4811, in _raise_from_invalid_response
    raise exceptions.from_http_status(response.status_code, message, response=response)
google.api_core.exceptions.Forbidden: 403 POST https://storage.googleapis.com/upload/storage/v1/b/ds525-capstone-test-49/o?uploadType=multipart: {
  "error": {
    "code": 403,
    "message": "swu-ds525-capstone-49@ds525-capstone.iam.gserviceaccount.com does not have storage.objects.create access to the Google Cloud Storage object. Permission 'storage.objects.create' denied on resource (or it may not exist).",
    "errors": [
      {
        "message": "swu-ds525-capstone-49@ds525-capstone.iam.gserviceaccount.com does not have storage.objects.create access to the Google Cloud Storage object. Permission 'storage.objects.create' denied on resource (or it may not exist).",
        "domain": "global",
        "reason": "forbidden"
      }
    ]
  }
}
: ('Request failed with status code', 403, 'Expected one of', <HTTPStatus.OK: 200>)
[2024-03-25T19:01:52.839+0000] {taskinstance.py:1149} INFO - Marking task as FAILED. dag_id=test_get_up_gcs, task_id=upload_to_gcs, execution_date=20240325T185723, start_date=20240325T190151, end_date=20240325T190152
[2024-03-25T19:01:52.876+0000] {standard_task_runner.py:107} ERROR - Failed to execute job 43 for task upload_to_gcs (403 POST https://storage.googleapis.com/upload/storage/v1/b/ds525-capstone-test-49/o?uploadType=multipart: {
  "error": {
    "code": 403,
    "message": "swu-ds525-capstone-49@ds525-capstone.iam.gserviceaccount.com does not have storage.objects.create access to the Google Cloud Storage object. Permission 'storage.objects.create' denied on resource (or it may not exist).",
    "errors": [
      {
        "message": "swu-ds525-capstone-49@ds525-capstone.iam.gserviceaccount.com does not have storage.objects.create access to the Google Cloud Storage object. Permission 'storage.objects.create' denied on resource (or it may not exist).",
        "domain": "global",
        "reason": "forbidden"
      }
    ]
  }
}
: ('Request failed with status code', 403, 'Expected one of', <HTTPStatus.OK: 200>); 4225)
[2024-03-25T19:01:52.913+0000] {local_task_job_runner.py:234} INFO - Task exited with return code 1
[2024-03-25T19:01:52.958+0000] {taskinstance.py:3312} INFO - 0 downstream tasks scheduled from follow-on schedule check
