[2024-03-25T19:21:48.201+0000] {taskinstance.py:1979} INFO - Dependencies all met for dep_context=non-requeueable deps ti=<TaskInstance: test_get_up_gcs.upload_to_gcs manual__2024-03-25T19:11:50.247729+00:00 [queued]>
[2024-03-25T19:21:48.234+0000] {taskinstance.py:1979} INFO - Dependencies all met for dep_context=requeueable deps ti=<TaskInstance: test_get_up_gcs.upload_to_gcs manual__2024-03-25T19:11:50.247729+00:00 [queued]>
[2024-03-25T19:21:48.235+0000] {taskinstance.py:2193} INFO - Starting attempt 4 of 4
[2024-03-25T19:21:48.284+0000] {taskinstance.py:2217} INFO - Executing <Task(PythonOperator): upload_to_gcs> on 2024-03-25 19:11:50.247729+00:00
[2024-03-25T19:21:48.297+0000] {standard_task_runner.py:60} INFO - Started process 4890 to run task
[2024-03-25T19:21:48.309+0000] {standard_task_runner.py:87} INFO - Running: ['***', 'tasks', 'run', 'test_get_up_gcs', 'upload_to_gcs', 'manual__2024-03-25T19:11:50.247729+00:00', '--job-id', '52', '--raw', '--subdir', 'DAGS_FOLDER/test_get_up_gcs.py', '--cfg-path', '/tmp/tmphs_sp0xn']
[2024-03-25T19:21:48.317+0000] {standard_task_runner.py:88} INFO - Job 52: Subtask upload_to_gcs
[2024-03-25T19:21:48.495+0000] {task_command.py:423} INFO - Running <TaskInstance: test_get_up_gcs.upload_to_gcs manual__2024-03-25T19:11:50.247729+00:00 [running]> on host c5a6ac367c49
[2024-03-25T19:21:48.797+0000] {taskinstance.py:2513} INFO - Exporting env vars: AIRFLOW_CTX_DAG_OWNER='***' AIRFLOW_CTX_DAG_ID='test_get_up_gcs' AIRFLOW_CTX_TASK_ID='upload_to_gcs' AIRFLOW_CTX_EXECUTION_DATE='2024-03-25T19:11:50.247729+00:00' AIRFLOW_CTX_TRY_NUMBER='4' AIRFLOW_CTX_DAG_RUN_ID='manual__2024-03-25T19:11:50.247729+00:00'
[2024-03-25T19:21:48.802+0000] {test_get_up_gcs.py:74} INFO - local file path : /opt/***/dags/
[2024-03-25T19:21:48.804+0000] {test_get_up_gcs.py:75} INFO - bucket name : ds525-capstone-test-49
[2024-03-25T19:21:48.806+0000] {test_get_up_gcs.py:76} INFO - dst : gs://ds525-capstone-test-49/
[2024-03-25T19:21:48.807+0000] {taskinstance.py:2731} ERROR - Task failed with exception
Traceback (most recent call last):
  File "/home/airflow/.local/lib/python3.8/site-packages/airflow/models/taskinstance.py", line 444, in _execute_task
    result = _execute_callable(context=context, **execute_callable_kwargs)
  File "/home/airflow/.local/lib/python3.8/site-packages/airflow/models/taskinstance.py", line 414, in _execute_callable
    return execute_callable(context=context, **execute_callable_kwargs)
  File "/home/airflow/.local/lib/python3.8/site-packages/airflow/operators/python.py", line 200, in execute
    return_value = self.execute_callable()
  File "/home/airflow/.local/lib/python3.8/site-packages/airflow/operators/python.py", line 217, in execute_callable
    return self.python_callable(*self.op_args, **self.op_kwargs)
  File "/opt/airflow/dags/test_get_up_gcs.py", line 84, in upload_data
    dag=dag
NameError: name 'dag' is not defined
[2024-03-25T19:21:48.836+0000] {taskinstance.py:1149} INFO - Marking task as FAILED. dag_id=test_get_up_gcs, task_id=upload_to_gcs, execution_date=20240325T191150, start_date=20240325T192148, end_date=20240325T192148
[2024-03-25T19:21:48.877+0000] {standard_task_runner.py:107} ERROR - Failed to execute job 52 for task upload_to_gcs (name 'dag' is not defined; 4890)
[2024-03-25T19:21:48.921+0000] {local_task_job_runner.py:234} INFO - Task exited with return code 1
[2024-03-25T19:21:48.987+0000] {taskinstance.py:3312} INFO - 0 downstream tasks scheduled from follow-on schedule check
