[2024-03-25T19:17:14.112+0000] {taskinstance.py:1979} INFO - Dependencies all met for dep_context=non-requeueable deps ti=<TaskInstance: test_get_up_gcs.upload_to_gcs manual__2024-03-25T19:11:50.247729+00:00 [queued]>
[2024-03-25T19:17:14.138+0000] {taskinstance.py:1979} INFO - Dependencies all met for dep_context=requeueable deps ti=<TaskInstance: test_get_up_gcs.upload_to_gcs manual__2024-03-25T19:11:50.247729+00:00 [queued]>
[2024-03-25T19:17:14.139+0000] {taskinstance.py:2193} INFO - Starting attempt 3 of 3
[2024-03-25T19:17:14.180+0000] {taskinstance.py:2217} INFO - Executing <Task(LocalFilesystemToGCSOperator): upload_to_gcs> on 2024-03-25 19:11:50.247729+00:00
[2024-03-25T19:17:14.192+0000] {standard_task_runner.py:60} INFO - Started process 4739 to run task
[2024-03-25T19:17:14.202+0000] {standard_task_runner.py:87} INFO - Running: ['***', 'tasks', 'run', 'test_get_up_gcs', 'upload_to_gcs', 'manual__2024-03-25T19:11:50.247729+00:00', '--job-id', '50', '--raw', '--subdir', 'DAGS_FOLDER/test_get_up_gcs.py', '--cfg-path', '/tmp/tmp9zlnsnc7']
[2024-03-25T19:17:14.209+0000] {standard_task_runner.py:88} INFO - Job 50: Subtask upload_to_gcs
[2024-03-25T19:17:14.337+0000] {task_command.py:423} INFO - Running <TaskInstance: test_get_up_gcs.upload_to_gcs manual__2024-03-25T19:11:50.247729+00:00 [running]> on host c5a6ac367c49
[2024-03-25T19:17:14.576+0000] {taskinstance.py:2513} INFO - Exporting env vars: AIRFLOW_CTX_DAG_OWNER='***' AIRFLOW_CTX_DAG_ID='test_get_up_gcs' AIRFLOW_CTX_TASK_ID='upload_to_gcs' AIRFLOW_CTX_EXECUTION_DATE='2024-03-25T19:11:50.247729+00:00' AIRFLOW_CTX_TRY_NUMBER='3' AIRFLOW_CTX_DAG_RUN_ID='manual__2024-03-25T19:11:50.247729+00:00'
[2024-03-25T19:17:14.602+0000] {connection.py:269} WARNING - Connection schemes (type: google_cloud_platform) shall not contain '_' according to RFC3986.
[2024-03-25T19:17:14.614+0000] {base.py:83} INFO - Using connection ID 'my_gcp_conn' for task execution.
[2024-03-25T19:17:14.993+0000] {taskinstance.py:2731} ERROR - Task failed with exception
Traceback (most recent call last):
  File "/home/airflow/.local/lib/python3.8/site-packages/airflow/models/taskinstance.py", line 444, in _execute_task
    result = _execute_callable(context=context, **execute_callable_kwargs)
  File "/home/airflow/.local/lib/python3.8/site-packages/airflow/models/taskinstance.py", line 414, in _execute_callable
    return execute_callable(context=context, **execute_callable_kwargs)
  File "/home/airflow/.local/lib/python3.8/site-packages/airflow/providers/google/cloud/transfers/local_to_gcs.py", line 110, in execute
    hook.upload(
  File "/home/airflow/.local/lib/python3.8/site-packages/airflow/providers/google/cloud/hooks/gcs.py", line 551, in upload
    _call_with_retry(
  File "/home/airflow/.local/lib/python3.8/site-packages/airflow/providers/google/cloud/hooks/gcs.py", line 509, in _call_with_retry
    f()
  File "/home/airflow/.local/lib/python3.8/site-packages/google/cloud/storage/blob.py", line 2949, in upload_from_filename
    self._handle_filename_and_upload(
  File "/home/airflow/.local/lib/python3.8/site-packages/google/cloud/storage/blob.py", line 2817, in _handle_filename_and_upload
    with open(filename, "rb") as file_obj:
IsADirectoryError: [Errno 21] Is a directory: '/opt/airflow/dags/'
[2024-03-25T19:17:15.018+0000] {taskinstance.py:1149} INFO - Marking task as FAILED. dag_id=test_get_up_gcs, task_id=upload_to_gcs, execution_date=20240325T191150, start_date=20240325T191714, end_date=20240325T191715
[2024-03-25T19:17:15.050+0000] {standard_task_runner.py:107} ERROR - Failed to execute job 50 for task upload_to_gcs ([Errno 21] Is a directory: '/opt/airflow/dags/'; 4739)
[2024-03-25T19:17:15.098+0000] {local_task_job_runner.py:234} INFO - Task exited with return code 1
[2024-03-25T19:17:15.149+0000] {taskinstance.py:3312} INFO - 0 downstream tasks scheduled from follow-on schedule check
