[2024-04-02T17:16:58.215+0000] {taskinstance.py:1979} INFO - Dependencies all met for dep_context=non-requeueable deps ti=<TaskInstance: test_get_air4thai.get_data_api manual__2024-04-02T16:57:34.323519+00:00 [queued]>
[2024-04-02T17:16:58.244+0000] {taskinstance.py:1979} INFO - Dependencies all met for dep_context=requeueable deps ti=<TaskInstance: test_get_air4thai.get_data_api manual__2024-04-02T16:57:34.323519+00:00 [queued]>
[2024-04-02T17:16:58.245+0000] {taskinstance.py:2193} INFO - Starting attempt 8 of 8
[2024-04-02T17:16:58.295+0000] {taskinstance.py:2217} INFO - Executing <Task(PythonOperator): get_data_api> on 2024-04-02 16:57:34.323519+00:00
[2024-04-02T17:16:58.308+0000] {standard_task_runner.py:60} INFO - Started process 236988 to run task
[2024-04-02T17:16:58.320+0000] {standard_task_runner.py:87} INFO - Running: ['***', 'tasks', 'run', 'test_get_air4thai', 'get_data_api', 'manual__2024-04-02T16:57:34.323519+00:00', '--job-id', '263', '--raw', '--subdir', 'DAGS_FOLDER/test_get_air4thai.py', '--cfg-path', '/tmp/tmpe7acxiw7']
[2024-04-02T17:16:58.327+0000] {standard_task_runner.py:88} INFO - Job 263: Subtask get_data_api
[2024-04-02T17:16:58.464+0000] {task_command.py:423} INFO - Running <TaskInstance: test_get_air4thai.get_data_api manual__2024-04-02T16:57:34.323519+00:00 [running]> on host c5a6ac367c49
[2024-04-02T17:16:58.687+0000] {taskinstance.py:2513} INFO - Exporting env vars: AIRFLOW_CTX_DAG_OWNER='***' AIRFLOW_CTX_DAG_ID='test_get_air4thai' AIRFLOW_CTX_TASK_ID='get_data_api' AIRFLOW_CTX_EXECUTION_DATE='2024-04-02T16:57:34.323519+00:00' AIRFLOW_CTX_TRY_NUMBER='8' AIRFLOW_CTX_DAG_RUN_ID='manual__2024-04-02T16:57:34.323519+00:00'
[2024-04-02T17:16:58.839+0000] {taskinstance.py:2731} ERROR - Task failed with exception
Traceback (most recent call last):
  File "/home/airflow/.local/lib/python3.8/site-packages/airflow/models/taskinstance.py", line 444, in _execute_task
    result = _execute_callable(context=context, **execute_callable_kwargs)
  File "/home/airflow/.local/lib/python3.8/site-packages/airflow/models/taskinstance.py", line 414, in _execute_callable
    return execute_callable(context=context, **execute_callable_kwargs)
  File "/home/airflow/.local/lib/python3.8/site-packages/airflow/operators/python.py", line 200, in execute
    return_value = self.execute_callable()
  File "/home/airflow/.local/lib/python3.8/site-packages/airflow/operators/python.py", line 217, in execute_callable
    return self.python_callable(*self.op_args, **self.op_kwargs)
  File "/opt/airflow/dags/test_get_air4thai.py", line 27, in _get_data_api
    f_datetime = current_datetime_local.strftime("%Y_%m_%d_%H00")
NameError: name 'current_datetime_local' is not defined
[2024-04-02T17:16:58.862+0000] {taskinstance.py:1149} INFO - Marking task as FAILED. dag_id=test_get_air4thai, task_id=get_data_api, execution_date=20240402T165734, start_date=20240402T171658, end_date=20240402T171658
[2024-04-02T17:16:58.898+0000] {standard_task_runner.py:107} ERROR - Failed to execute job 263 for task get_data_api (name 'current_datetime_local' is not defined; 236988)
[2024-04-02T17:16:58.934+0000] {local_task_job_runner.py:234} INFO - Task exited with return code 1
[2024-04-02T17:16:58.985+0000] {taskinstance.py:3312} INFO - 0 downstream tasks scheduled from follow-on schedule check
